* Running on local URL:  http://localhost:8844

Could not create share link. Please check your internet connection or our status page: https://status.gradio.app.
[31mERROR[0m:    Exception in ASGI application
Traceback (most recent call last):
  File "c:\Python312\Lib\site-packages\starlette\responses.py", line 332, in __call__
    stat_result = await anyio.to_thread.run_sync(os.stat, self.path)
                  ^^^^^^^^^^^^^^^^^^^^^^^^^^^^^^^^^^^^^^^^^^^^^^^^^^
  File "c:\Python312\Lib\site-packages\anyio\to_thread.py", line 56, in run_sync
    return await get_async_backend().run_sync_in_worker_thread(
           ^^^^^^^^^^^^^^^^^^^^^^^^^^^^^^^^^^^^^^^^^^^^^^^^^^^^
  File "c:\Python312\Lib\site-packages\anyio\_backends\_asyncio.py", line 2461, in run_sync_in_worker_thread
    return await future
           ^^^^^^^^^^^^
  File "c:\Python312\Lib\site-packages\anyio\_backends\_asyncio.py", line 962, in run
    result = context.run(func, *args)
             ^^^^^^^^^^^^^^^^^^^^^^^^
FileNotFoundError: [WinError 3] The system cannot find the path specified: 'path/to/favicon.ico'

During handling of the above exception, another exception occurred:

Traceback (most recent call last):
  File "c:\Python312\Lib\site-packages\uvicorn\protocols\http\httptools_impl.py", line 409, in run_asgi
    result = await app(  # type: ignore[func-returns-value]
             ^^^^^^^^^^^^^^^^^^^^^^^^^^^^^^^^^^^^^^^^^^^^^^
  File "c:\Python312\Lib\site-packages\uvicorn\middleware\proxy_headers.py", line 60, in __call__
    return await self.app(scope, receive, send)
           ^^^^^^^^^^^^^^^^^^^^^^^^^^^^^^^^^^^^
  File "C:\Users\TMB\AppData\Roaming\Python\Python312\site-packages\fastapi\applications.py", line 1054, in __call__
    await super().__call__(scope, receive, send)
  File "c:\Python312\Lib\site-packages\starlette\applications.py", line 113, in __call__
    await self.middleware_stack(scope, receive, send)
  File "c:\Python312\Lib\site-packages\starlette\middleware\errors.py", line 187, in __call__
    raise exc
  File "c:\Python312\Lib\site-packages\starlette\middleware\errors.py", line 165, in __call__
    await self.app(scope, receive, _send)
  File "C:\Users\TMB\AppData\Roaming\Python\Python312\site-packages\gradio\route_utils.py", line 789, in __call__
    await self.app(scope, receive, send)
  File "c:\Python312\Lib\site-packages\starlette\middleware\exceptions.py", line 62, in __call__
    await wrap_app_handling_exceptions(self.app, conn)(scope, receive, send)
  File "c:\Python312\Lib\site-packages\starlette\_exception_handler.py", line 53, in wrapped_app
    raise exc
  File "c:\Python312\Lib\site-packages\starlette\_exception_handler.py", line 42, in wrapped_app
    await app(scope, receive, sender)
  File "c:\Python312\Lib\site-packages\starlette\routing.py", line 715, in __call__
    await self.middleware_stack(scope, receive, send)
  File "c:\Python312\Lib\site-packages\starlette\routing.py", line 735, in app
    await route.handle(scope, receive, send)
  File "c:\Python312\Lib\site-packages\starlette\routing.py", line 288, in handle
    await self.app(scope, receive, send)
  File "c:\Python312\Lib\site-packages\starlette\routing.py", line 76, in app
    await wrap_app_handling_exceptions(app, request)(scope, receive, send)
  File "c:\Python312\Lib\site-packages\starlette\_exception_handler.py", line 53, in wrapped_app
    raise exc
  File "c:\Python312\Lib\site-packages\starlette\_exception_handler.py", line 42, in wrapped_app
    await app(scope, receive, sender)
  File "c:\Python312\Lib\site-packages\starlette\routing.py", line 74, in app
    await response(scope, receive, send)
  File "c:\Python312\Lib\site-packages\starlette\responses.py", line 335, in __call__
    raise RuntimeError(f"File at path {self.path} does not exist.")
RuntimeError: File at path path/to/favicon.ico does not exist.
